Workbook
Name 手套名冊: '資料源(請謹慎編輯)'!$B$243:$B$270
Name 主武名冊: '資料源(請謹慎編輯)'!$B$59:$B$99
Name 衣服名冊: '資料源(請謹慎編輯)'!$B$170:$B$241
Name 角色上限: '資料源(請謹慎編輯)'!$B$314:$B$324
Name 副武名冊: '資料源(請謹慎編輯)'!$B$101:$B$120
Name 飾品名冊: '資料源(請謹慎編輯)'!$B$2:$B$25
Name 鞋子名冊: '資料源(請謹慎編輯)'!$B$272:$B$299
Name 頭盔名冊: '資料源(請謹慎編輯)'!$B$122:$B$168
Name 職業名冊: '資料源(請謹慎編輯)'!$B$301:$B$311
Name 寶物名冊: '資料源(請謹慎編輯)'!$B$27:$B$57

Sheet 選單
A1: 位置 | B1: 裝備名稱 | C1: 炮術 | D1: 水平射擊 | E1: 速射 | F1: 貫穿 | G1: 彈道學 | H1: 水雷 | I1: 齊射 | J1: 修理 | K1: 掠奪 | L1: 迴避 | M1: 應急 | N1: 手術 | O1: 划船 | P1: 劍術 | Q1: 突擊 | R1: 戰術 | S1: 射擊 | T1: 防禦 | U1: 識破 | V1: 猛擊 | W1: 迅捷 | X1: 接舷 | Y1: 操舵 | Z1: 搜尋
A2: 飾品 | B2: 丁卡族戒指(質變) | C2: {=XLOOKUP($B2, '資料源(請謹慎編輯)'!$B:$B, '資料源(請謹慎編輯)'!C:C, 0)} | D2: {=XLOOKUP($B2, '資料源(請謹慎編輯)'!$B:$B, '資料源(請謹慎編輯)'!D:D, 0)} | E2: {=XLOOKUP($B2, '資料源(請謹慎編輯)'!$B:$B, '資料源(請謹慎編輯)'!E:E, 0)} | F2: {=XLOOKUP($B2, '資料源(請謹慎編輯)'!$B:$B, '資料源(請謹慎編輯)'!F:F, 0)} | G2: {=XLOOKUP($B2, '資料源(請謹慎編輯)'!$B:$B, '資料源(請謹慎編輯)'!G:G, 0)} | H2: {=XLOOKUP($B2, '資料源(請謹慎編輯)'!$B:$B, '資料源(請謹慎編輯)'!H:H, 0)} | I2: {=XLOOKUP($B2, '資料源(請謹慎編輯)'!$B:$B, '資料源(請謹慎編輯)'!I:I, 0)} | J2: {=XLOOKUP($B2, '資料源(請謹慎編輯)'!$B:$B, '資料源(請謹慎編輯)'!J:J, 0)} | K2: {=XLOOKUP($B2, '資料源(請謹慎編輯)'!$B:$B, '資料源(請謹慎編輯)'!K:K, 0)} | L2: {=XLOOKUP($B2, '資料源(請謹慎編輯)'!$B:$B, '資料源(請謹慎編輯)'!L:L, 0)} | M2: {=XLOOKUP($B2, '資料源(請謹慎編輯)'!$B:$B, '資料源(請謹慎編輯)'!M:M, 0)} | N2: {=XLOOKUP($B2, '資料源(請謹慎編輯)'!$B:$B, '資料源(請謹慎編輯)'!N:N, 0)} | O2: {=XLOOKUP($B2, '資料源(請謹慎編輯)'!$B:$B, '資料源(請謹慎編輯)'!O:O, 0)} | P2: {=XLOOKUP($B2, '資料源(請謹慎編輯)'!$B:$B, '資料源(請謹慎編輯)'!P:P, 0)} | Q2: {=XLOOKUP($B2, '資料源(請謹慎編輯)'!$B:$B, '資料源(請謹慎編輯)'!Q:Q, 0)} | R2: {=XLOOKUP($B2, '資料源(請謹慎編輯)'!$B:$B, '資料源(請謹慎編輯)'!R:R, 0)} | S2: {=XLOOKUP($B2, '資料源(請謹慎編輯)'!$B:$B, '資料源(請謹慎編輯)'!S:S, 0)} | T2: {=XLOOKUP($B2, '資料源(請謹慎編輯)'!$B:$B, '資料源(請謹慎編輯)'!T:T, 0)} | U2: {=XLOOKUP($B2, '資料源(請謹慎編輯)'!$B:$B, '資料源(請謹慎編輯)'!U:U, 0)} | V2: {=XLOOKUP($B2, '資料源(請謹慎編輯)'!$B:$B, '資料源(請謹慎編輯)'!V:V, 0)} | W2: {=XLOOKUP($B2, '資料源(請謹慎編輯)'!$B:$B, '資料源(請謹慎編輯)'!W:W, 0)} | X2: {=XLOOKUP($B2, '資料源(請謹慎編輯)'!$B:$B, '資料源(請謹慎編輯)'!X:X, 0)} | Y2: {=XLOOKUP($B2, '資料源(請謹慎編輯)'!$B:$B, '資料源(請謹慎編輯)'!Y:Y, 0)} | Z2: {=XLOOKUP($B2, '資料源(請謹慎編輯)'!$B:$B, '資料源(請謹慎編輯)'!Z:Z, 0)}
A3: 飾品 | B3: 丁卡族戒指(質變) | C3: {=XLOOKUP($B3, '資料源(請謹慎編輯)'!$B:$B, '資料源(請謹慎編輯)'!C:C, 0)} | D3: {=XLOOKUP($B3, '資料源(請謹慎編輯)'!$B:$B, '資料源(請謹慎編輯)'!D:D, 0)} | E3: {=XLOOKUP($B3, '資料源(請謹慎編輯)'!$B:$B, '資料源(請謹慎編輯)'!E:E, 0)} | F3: {=XLOOKUP($B3, '資料源(請謹慎編輯)'!$B:$B, '資料源(請謹慎編輯)'!F:F, 0)} | G3: {=XLOOKUP($B3, '資料源(請謹慎編輯)'!$B:$B, '資料源(請謹慎編輯)'!G:G, 0)} | H3: {=XLOOKUP($B3, '資料源(請謹慎編輯)'!$B:$B, '資料源(請謹慎編輯)'!H:H, 0)} | I3: {=XLOOKUP($B3, '資料源(請謹慎編輯)'!$B:$B, '資料源(請謹慎編輯)'!I:I, 0)} | J3: {=XLOOKUP($B3, '資料源(請謹慎編輯)'!$B:$B, '資料源(請謹慎編輯)'!J:J, 0)} | K3: {=XLOOKUP($B3, '資料源(請謹慎編輯)'!$B:$B, '資料源(請謹慎編輯)'!K:K, 0)} | L3: {=XLOOKUP($B3, '資料源(請謹慎編輯)'!$B:$B, '資料源(請謹慎編輯)'!L:L, 0)} | M3: {=XLOOKUP($B3, '資料源(請謹慎編輯)'!$B:$B, '資料源(請謹慎編輯)'!M:M, 0)} | N3: {=XLOOKUP($B3, '資料源(請謹慎編輯)'!$B:$B, '資料源(請謹慎編輯)'!N:N, 0)} | O3: {=XLOOKUP($B3, '資料源(請謹慎編輯)'!$B:$B, '資料源(請謹慎編輯)'!O:O, 0)} | P3: {=XLOOKUP($B3, '資料源(請謹慎編輯)'!$B:$B, '資料源(請謹慎編輯)'!P:P, 0)} | Q3: {=XLOOKUP($B3, '資料源(請謹慎編輯)'!$B:$B, '資料源(請謹慎編輯)'!Q:Q, 0)} | R3: {=XLOOKUP($B3, '資料源(請謹慎編輯)'!$B:$B, '資料源(請謹慎編輯)'!R:R, 0)} | S3: {=XLOOKUP($B3, '資料源(請謹慎編輯)'!$B:$B, '資料源(請謹慎編輯)'!S:S, 0)} | T3: {=XLOOKUP($B3, '資料源(請謹慎編輯)'!$B:$B, '資料源(請謹慎編輯)'!T:T, 0)} | U3: {=XLOOKUP($B3, '資料源(請謹慎編輯)'!$B:$B, '資料源(請謹慎編輯)'!U:U, 0)} | V3: {=XLOOKUP($B3, '資料源(請謹慎編輯)'!$B:$B, '資料源(請謹慎編輯)'!V:V, 0)} | W3: {=XLOOKUP($B3, '資料源(請謹慎編輯)'!$B:$B, '資料源(請謹慎編輯)'!W:W, 0)} | X3: {=XLOOKUP($B3, '資料源(請謹慎編輯)'!$B:$B, '資料源(請謹慎編輯)'!X:X, 0)} | Y3: {=XLOOKUP($B3, '資料源(請謹慎編輯)'!$B:$B, '資料源(請謹慎編輯)'!Y:Y, 0)} | Z3: {=XLOOKUP($B3, '資料源(請謹慎編輯)'!$B:$B, '資料源(請謹慎編輯)'!Z:Z, 0)}
A4: 寶物 | B4: 軍神的護身符 | C4: {=XLOOKUP($B4, '資料源(請謹慎編輯)'!$B:$B, '資料源(請謹慎編輯)'!C:C, 0)} | D4: {=XLOOKUP($B4, '資料源(請謹慎編輯)'!$B:$B, '資料源(請謹慎編輯)'!D:D, 0)} | E4: {=XLOOKUP($B4, '資料源(請謹慎編輯)'!$B:$B, '資料源(請謹慎編輯)'!E:E, 0)} | F4: {=XLOOKUP($B4, '資料源(請謹慎編輯)'!$B:$B, '資料源(請謹慎編輯)'!F:F, 0)} | G4: {=XLOOKUP($B4, '資料源(請謹慎編輯)'!$B:$B, '資料源(請謹慎編輯)'!G:G, 0)} | H4: {=XLOOKUP($B4, '資料源(請謹慎編輯)'!$B:$B, '資料源(請謹慎編輯)'!H:H, 0)} | I4: {=XLOOKUP($B4, '資料源(請謹慎編輯)'!$B:$B, '資料源(請謹慎編輯)'!I:I, 0)} | J4: {=XLOOKUP($B4, '資料源(請謹慎編輯)'!$B:$B, '資料源(請謹慎編輯)'!J:J, 0)} | K4: {=XLOOKUP($B4, '資料源(請謹慎編輯)'!$B:$B, '資料源(請謹慎編輯)'!K:K, 0)} | L4: {=XLOOKUP($B4, '資料源(請謹慎編輯)'!$B:$B, '資料源(請謹慎編輯)'!L:L, 0)} | M4: {=XLOOKUP($B4, '資料源(請謹慎編輯)'!$B:$B, '資料源(請謹慎編輯)'!M:M, 0)} | N4: {=XLOOKUP($B4, '資料源(請謹慎編輯)'!$B:$B, '資料源(請謹慎編輯)'!N:N, 0)} | O4: {=XLOOKUP($B4, '資料源(請謹慎編輯)'!$B:$B, '資料源(請謹慎編輯)'!O:O, 0)} | P4: {=XLOOKUP($B4, '資料源(請謹慎編輯)'!$B:$B, '資料源(請謹慎編輯)'!P:P, 0)} | Q4: {=XLOOKUP($B4, '資料源(請謹慎編輯)'!$B:$B, '資料源(請謹慎編輯)'!Q:Q, 0)} | R4: {=XLOOKUP($B4, '資料源(請謹慎編輯)'!$B:$B, '資料源(請謹慎編輯)'!R:R, 0)} | S4: {=XLOOKUP($B4, '資料源(請謹慎編輯)'!$B:$B, '資料源(請謹慎編輯)'!S:S, 0)} | T4: {=XLOOKUP($B4, '資料源(請謹慎編輯)'!$B:$B, '資料源(請謹慎編輯)'!T:T, 0)} | U4: {=XLOOKUP($B4, '資料源(請謹慎編輯)'!$B:$B, '資料源(請謹慎編輯)'!U:U, 0)} | V4: {=XLOOKUP($B4, '資料源(請謹慎編輯)'!$B:$B, '資料源(請謹慎編輯)'!V:V, 0)} | W4: {=XLOOKUP($B4, '資料源(請謹慎編輯)'!$B:$B, '資料源(請謹慎編輯)'!W:W, 0)} | X4: {=XLOOKUP($B4, '資料源(請謹慎編輯)'!$B:$B, '資料源(請謹慎編輯)'!X:X, 0)} | Y4: {=XLOOKUP($B4, '資料源(請謹慎編輯)'!$B:$B, '資料源(請謹慎編輯)'!Y:Y, 0)} | Z4: {=XLOOKUP($B4, '資料源(請謹慎編輯)'!$B:$B, '資料源(請謹慎編輯)'!Z:Z, 0)}
A5: 寶物 | B5: 軍神的護身符 | C5: {=XLOOKUP($B5, '資料源(請謹慎編輯)'!$B:$B, '資料源(請謹慎編輯)'!C:C, 0)} | D5: {=XLOOKUP($B5, '資料源(請謹慎編輯)'!$B:$B, '資料源(請謹慎編輯)'!D:D, 0)} | E5: {=XLOOKUP($B5, '資料源(請謹慎編輯)'!$B:$B, '資料源(請謹慎編輯)'!E:E, 0)} | F5: {=XLOOKUP($B5, '資料源(請謹慎編輯)'!$B:$B, '資料源(請謹慎編輯)'!F:F, 0)} | G5: {=XLOOKUP($B5, '資料源(請謹慎編輯)'!$B:$B, '資料源(請謹慎編輯)'!G:G, 0)} | H5: {=XLOOKUP($B5, '資料源(請謹慎編輯)'!$B:$B, '資料源(請謹慎編輯)'!H:H, 0)} | I5: {=XLOOKUP($B5, '資料源(請謹慎編輯)'!$B:$B, '資料源(請謹慎編輯)'!I:I, 0)} | J5: {=XLOOKUP($B5, '資料源(請謹慎編輯)'!$B:$B, '資料源(請謹慎編輯)'!J:J, 0)} | K5: {=XLOOKUP($B5, '資料源(請謹慎編輯)'!$B:$B, '資料源(請謹慎編輯)'!K:K, 0)} | L5: {=XLOOKUP($B5, '資料源(請謹慎編輯)'!$B:$B, '資料源(請謹慎編輯)'!L:L, 0)} | M5: {=XLOOKUP($B5, '資料源(請謹慎編輯)'!$B:$B, '資料源(請謹慎編輯)'!M:M, 0)} | N5: {=XLOOKUP($B5, '資料源(請謹慎編輯)'!$B:$B, '資料源(請謹慎編輯)'!N:N, 0)} | O5: {=XLOOKUP($B5, '資料源(請謹慎編輯)'!$B:$B, '資料源(請謹慎編輯)'!O:O, 0)} | P5: {=XLOOKUP($B5, '資料源(請謹慎編輯)'!$B:$B, '資料源(請謹慎編輯)'!P:P, 0)} | Q5: {=XLOOKUP($B5, '資料源(請謹慎編輯)'!$B:$B, '資料源(請謹慎編輯)'!Q:Q, 0)} | R5: {=XLOOKUP($B5, '資料源(請謹慎編輯)'!$B:$B, '資料源(請謹慎編輯)'!R:R, 0)} | S5: {=XLOOKUP($B5, '資料源(請謹慎編輯)'!$B:$B, '資料源(請謹慎編輯)'!S:S, 0)} | T5: {=XLOOKUP($B5, '資料源(請謹慎編輯)'!$B:$B, '資料源(請謹慎編輯)'!T:T, 0)} | U5: {=XLOOKUP($B5, '資料源(請謹慎編輯)'!$B:$B, '資料源(請謹慎編輯)'!U:U, 0)} | V5: {=XLOOKUP($B5, '資料源(請謹慎編輯)'!$B:$B, '資料源(請謹慎編輯)'!V:V, 0)} | W5: {=XLOOKUP($B5, '資料源(請謹慎編輯)'!$B:$B, '資料源(請謹慎編輯)'!W:W, 0)} | X5: {=XLOOKUP($B5, '資料源(請謹慎編輯)'!$B:$B, '資料源(請謹慎編輯)'!X:X, 0)} | Y5: {=XLOOKUP($B5, '資料源(請謹慎編輯)'!$B:$B, '資料源(請謹慎編輯)'!Y:Y, 0)} | Z5: {=XLOOKUP($B5, '資料源(請謹慎編輯)'!$B:$B, '資料源(請謹慎編輯)'!Z:Z, 0)}
A6: 主武 | B6: 西班牙將軍的權杖 | C6: {=XLOOKUP($B6, '資料源(請謹慎編輯)'!$B:$B, '資料源(請謹慎編輯)'!C:C, 0)} | D6: {=XLOOKUP($B6, '資料源(請謹慎編輯)'!$B:$B, '資料源(請謹慎編輯)'!D:D, 0)} | E6: {=XLOOKUP($B6, '資料源(請謹慎編輯)'!$B:$B, '資料源(請謹慎編輯)'!E:E, 0)} | F6: {=XLOOKUP($B6, '資料源(請謹慎編輯)'!$B:$B, '資料源(請謹慎編輯)'!F:F, 0)} | G6: {=XLOOKUP($B6, '資料源(請謹慎編輯)'!$B:$B, '資料源(請謹慎編輯)'!G:G, 0)} | H6: {=XLOOKUP($B6, '資料源(請謹慎編輯)'!$B:$B, '資料源(請謹慎編輯)'!H:H, 0)} | I6: {=XLOOKUP($B6, '資料源(請謹慎編輯)'!$B:$B, '資料源(請謹慎編輯)'!I:I, 0)} | J6: {=XLOOKUP($B6, '資料源(請謹慎編輯)'!$B:$B, '資料源(請謹慎編輯)'!J:J, 0)} | K6: {=XLOOKUP($B6, '資料源(請謹慎編輯)'!$B:$B, '資料源(請謹慎編輯)'!K:K, 0)} | L6: {=XLOOKUP($B6, '資料源(請謹慎編輯)'!$B:$B, '資料源(請謹慎編輯)'!L:L, 0)} | M6: {=XLOOKUP($B6, '資料源(請謹慎編輯)'!$B:$B, '資料源(請謹慎編輯)'!M:M, 0)} | N6: {=XLOOKUP($B6, '資料源(請謹慎編輯)'!$B:$B, '資料源(請謹慎編輯)'!N:N, 0)} | O6: {=XLOOKUP($B6, '資料源(請謹慎編輯)'!$B:$B, '資料源(請謹慎編輯)'!O:O, 0)} | P6: {=XLOOKUP($B6, '資料源(請謹慎編輯)'!$B:$B, '資料源(請謹慎編輯)'!P:P, 0)} | Q6: {=XLOOKUP($B6, '資料源(請謹慎編輯)'!$B:$B, '資料源(請謹慎編輯)'!Q:Q, 0)} | R6: {=XLOOKUP($B6, '資料源(請謹慎編輯)'!$B:$B, '資料源(請謹慎編輯)'!R:R, 0)} | S6: {=XLOOKUP($B6, '資料源(請謹慎編輯)'!$B:$B, '資料源(請謹慎編輯)'!S:S, 0)} | T6: {=XLOOKUP($B6, '資料源(請謹慎編輯)'!$B:$B, '資料源(請謹慎編輯)'!T:T, 0)} | U6: {=XLOOKUP($B6, '資料源(請謹慎編輯)'!$B:$B, '資料源(請謹慎編輯)'!U:U, 0)} | V6: {=XLOOKUP($B6, '資料源(請謹慎編輯)'!$B:$B, '資料源(請謹慎編輯)'!V:V, 0)} | W6: {=XLOOKUP($B6, '資料源(請謹慎編輯)'!$B:$B, '資料源(請謹慎編輯)'!W:W, 0)} | X6: {=XLOOKUP($B6, '資料源(請謹慎編輯)'!$B:$B, '資料源(請謹慎編輯)'!X:X, 0)} | Y6: {=XLOOKUP($B6, '資料源(請謹慎編輯)'!$B:$B, '資料源(請謹慎編輯)'!Y:Y, 0)} | Z6: {=XLOOKUP($B6, '資料源(請謹慎編輯)'!$B:$B, '資料源(請謹慎編輯)'!Z:Z, 0)}
A7: 副武 | B7: 波斯單刃短劍 | C7: {=XLOOKUP($B7, '資料源(請謹慎編輯)'!$B:$B, '資料源(請謹慎編輯)'!C:C, 0)} | D7: {=XLOOKUP($B7, '資料源(請謹慎編輯)'!$B:$B, '資料源(請謹慎編輯)'!D:D, 0)} | E7: {=XLOOKUP($B7, '資料源(請謹慎編輯)'!$B:$B, '資料源(請謹慎編輯)'!E:E, 0)} | F7: {=XLOOKUP($B7, '資料源(請謹慎編輯)'!$B:$B, '資料源(請謹慎編輯)'!F:F, 0)} | G7: {=XLOOKUP($B7, '資料源(請謹慎編輯)'!$B:$B, '資料源(請謹慎編輯)'!G:G, 0)} | H7: {=XLOOKUP($B7, '資料源(請謹慎編輯)'!$B:$B, '資料源(請謹慎編輯)'!H:H, 0)} | I7: {=XLOOKUP($B7, '資料源(請謹慎編輯)'!$B:$B, '資料源(請謹慎編輯)'!I:I, 0)} | J7: {=XLOOKUP($B7, '資料源(請謹慎編輯)'!$B:$B, '資料源(請謹慎編輯)'!J:J, 0)} | K7: {=XLOOKUP($B7, '資料源(請謹慎編輯)'!$B:$B, '資料源(請謹慎編輯)'!K:K, 0)} | L7: {=XLOOKUP($B7, '資料源(請謹慎編輯)'!$B:$B, '資料源(請謹慎編輯)'!L:L, 0)} | M7: {=XLOOKUP($B7, '資料源(請謹慎編輯)'!$B:$B, '資料源(請謹慎編輯)'!M:M, 0)} | N7: {=XLOOKUP($B7, '資料源(請謹慎編輯)'!$B:$B, '資料源(請謹慎編輯)'!N:N, 0)} | O7: {=XLOOKUP($B7, '資料源(請謹慎編輯)'!$B:$B, '資料源(請謹慎編輯)'!O:O, 0)} | P7: {=XLOOKUP($B7, '資料源(請謹慎編輯)'!$B:$B, '資料源(請謹慎編輯)'!P:P, 0)} | Q7: {=XLOOKUP($B7, '資料源(請謹慎編輯)'!$B:$B, '資料源(請謹慎編輯)'!Q:Q, 0)} | R7: {=XLOOKUP($B7, '資料源(請謹慎編輯)'!$B:$B, '資料源(請謹慎編輯)'!R:R, 0)} | S7: {=XLOOKUP($B7, '資料源(請謹慎編輯)'!$B:$B, '資料源(請謹慎編輯)'!S:S, 0)} | T7: {=XLOOKUP($B7, '資料源(請謹慎編輯)'!$B:$B, '資料源(請謹慎編輯)'!T:T, 0)} | U7: {=XLOOKUP($B7, '資料源(請謹慎編輯)'!$B:$B, '資料源(請謹慎編輯)'!U:U, 0)} | V7: {=XLOOKUP($B7, '資料源(請謹慎編輯)'!$B:$B, '資料源(請謹慎編輯)'!V:V, 0)} | W7: {=XLOOKUP($B7, '資料源(請謹慎編輯)'!$B:$B, '資料源(請謹慎編輯)'!W:W, 0)} | X7: {=XLOOKUP($B7, '資料源(請謹慎編輯)'!$B:$B, '資料源(請謹慎編輯)'!X:X, 0)} | Y7: {=XLOOKUP($B7, '資料源(請謹慎編輯)'!$B:$B, '資料源(請謹慎編輯)'!Y:Y, 0)} | Z7: {=XLOOKUP($B7, '資料源(請謹慎編輯)'!$B:$B, '資料源(請謹慎編輯)'!Z:Z, 0)}
A8: 頭盔 | B8: 阿爾維達的頭盔 | C8: {=XLOOKUP($B8, '資料源(請謹慎編輯)'!$B:$B, '資料源(請謹慎編輯)'!C:C, 0)} | D8: {=XLOOKUP($B8, '資料源(請謹慎編輯)'!$B:$B, '資料源(請謹慎編輯)'!D:D, 0)} | E8: {=XLOOKUP($B8, '資料源(請謹慎編輯)'!$B:$B, '資料源(請謹慎編輯)'!E:E, 0)} | F8: {=XLOOKUP($B8, '資料源(請謹慎編輯)'!$B:$B, '資料源(請謹慎編輯)'!F:F, 0)} | G8: {=XLOOKUP($B8, '資料源(請謹慎編輯)'!$B:$B, '資料源(請謹慎編輯)'!G:G, 0)} | H8: {=XLOOKUP($B8, '資料源(請謹慎編輯)'!$B:$B, '資料源(請謹慎編輯)'!H:H, 0)} | I8: {=XLOOKUP($B8, '資料源(請謹慎編輯)'!$B:$B, '資料源(請謹慎編輯)'!I:I, 0)} | J8: {=XLOOKUP($B8, '資料源(請謹慎編輯)'!$B:$B, '資料源(請謹慎編輯)'!J:J, 0)} | K8: {=XLOOKUP($B8, '資料源(請謹慎編輯)'!$B:$B, '資料源(請謹慎編輯)'!K:K, 0)} | L8: {=XLOOKUP($B8, '資料源(請謹慎編輯)'!$B:$B, '資料源(請謹慎編輯)'!L:L, 0)} | M8: {=XLOOKUP($B8, '資料源(請謹慎編輯)'!$B:$B, '資料源(請謹慎編輯)'!M:M, 0)} | N8: {=XLOOKUP($B8, '資料源(請謹慎編輯)'!$B:$B, '資料源(請謹慎編輯)'!N:N, 0)} | O8: {=XLOOKUP($B8, '資料源(請謹慎編輯)'!$B:$B, '資料源(請謹慎編輯)'!O:O, 0)} | P8: {=XLOOKUP($B8, '資料源(請謹慎編輯)'!$B:$B, '資料源(請謹慎編輯)'!P:P, 0)} | Q8: {=XLOOKUP($B8, '資料源(請謹慎編輯)'!$B:$B, '資料源(請謹慎編輯)'!Q:Q, 0)} | R8: {=XLOOKUP($B8, '資料源(請謹慎編輯)'!$B:$B, '資料源(請謹慎編輯)'!R:R, 0)} | S8: {=XLOOKUP($B8, '資料源(請謹慎編輯)'!$B:$B, '資料源(請謹慎編輯)'!S:S, 0)} | T8: {=XLOOKUP($B8, '資料源(請謹慎編輯)'!$B:$B, '資料源(請謹慎編輯)'!T:T, 0)} | U8: {=XLOOKUP($B8, '資料源(請謹慎編輯)'!$B:$B, '資料源(請謹慎編輯)'!U:U, 0)} | V8: {=XLOOKUP($B8, '資料源(請謹慎編輯)'!$B:$B, '資料源(請謹慎編輯)'!V:V, 0)} | W8: {=XLOOKUP($B8, '資料源(請謹慎編輯)'!$B:$B, '資料源(請謹慎編輯)'!W:W, 0)} | X8: {=XLOOKUP($B8, '資料源(請謹慎編輯)'!$B:$B, '資料源(請謹慎編輯)'!X:X, 0)} | Y8: {=XLOOKUP($B8, '資料源(請謹慎編輯)'!$B:$B, '資料源(請謹慎編輯)'!Y:Y, 0)} | Z8: {=XLOOKUP($B8, '資料源(請謹慎編輯)'!$B:$B, '資料源(請謹慎編輯)'!Z:Z, 0)}
A9: 衣服 | B9: 海軍上將胸甲 | C9: {=XLOOKUP($B9, '資料源(請謹慎編輯)'!$B:$B, '資料源(請謹慎編輯)'!C:C, 0)} | D9: {=XLOOKUP($B9, '資料源(請謹慎編輯)'!$B:$B, '資料源(請謹慎編輯)'!D:D, 0)} | E9: {=XLOOKUP($B9, '資料源(請謹慎編輯)'!$B:$B, '資料源(請謹慎編輯)'!E:E, 0)} | F9: {=XLOOKUP($B9, '資料源(請謹慎編輯)'!$B:$B, '資料源(請謹慎編輯)'!F:F, 0)} | G9: {=XLOOKUP($B9, '資料源(請謹慎編輯)'!$B:$B, '資料源(請謹慎編輯)'!G:G, 0)} | H9: {=XLOOKUP($B9, '資料源(請謹慎編輯)'!$B:$B, '資料源(請謹慎編輯)'!H:H, 0)} | I9: {=XLOOKUP($B9, '資料源(請謹慎編輯)'!$B:$B, '資料源(請謹慎編輯)'!I:I, 0)} | J9: {=XLOOKUP($B9, '資料源(請謹慎編輯)'!$B:$B, '資料源(請謹慎編輯)'!J:J, 0)} | K9: {=XLOOKUP($B9, '資料源(請謹慎編輯)'!$B:$B, '資料源(請謹慎編輯)'!K:K, 0)} | L9: {=XLOOKUP($B9, '資料源(請謹慎編輯)'!$B:$B, '資料源(請謹慎編輯)'!L:L, 0)} | M9: {=XLOOKUP($B9, '資料源(請謹慎編輯)'!$B:$B, '資料源(請謹慎編輯)'!M:M, 0)} | N9: {=XLOOKUP($B9, '資料源(請謹慎編輯)'!$B:$B, '資料源(請謹慎編輯)'!N:N, 0)} | O9: {=XLOOKUP($B9, '資料源(請謹慎編輯)'!$B:$B, '資料源(請謹慎編輯)'!O:O, 0)} | P9: {=XLOOKUP($B9, '資料源(請謹慎編輯)'!$B:$B, '資料源(請謹慎編輯)'!P:P, 0)} | Q9: {=XLOOKUP($B9, '資料源(請謹慎編輯)'!$B:$B, '資料源(請謹慎編輯)'!Q:Q, 0)} | R9: {=XLOOKUP($B9, '資料源(請謹慎編輯)'!$B:$B, '資料源(請謹慎編輯)'!R:R, 0)} | S9: {=XLOOKUP($B9, '資料源(請謹慎編輯)'!$B:$B, '資料源(請謹慎編輯)'!S:S, 0)} | T9: {=XLOOKUP($B9, '資料源(請謹慎編輯)'!$B:$B, '資料源(請謹慎編輯)'!T:T, 0)} | U9: {=XLOOKUP($B9, '資料源(請謹慎編輯)'!$B:$B, '資料源(請謹慎編輯)'!U:U, 0)} | V9: {=XLOOKUP($B9, '資料源(請謹慎編輯)'!$B:$B, '資料源(請謹慎編輯)'!V:V, 0)} | W9: {=XLOOKUP($B9, '資料源(請謹慎編輯)'!$B:$B, '資料源(請謹慎編輯)'!W:W, 0)} | X9: {=XLOOKUP($B9, '資料源(請謹慎編輯)'!$B:$B, '資料源(請謹慎編輯)'!X:X, 0)} | Y9: {=XLOOKUP($B9, '資料源(請謹慎編輯)'!$B:$B, '資料源(請謹慎編輯)'!Y:Y, 0)} | Z9: {=XLOOKUP($B9, '資料源(請謹慎編輯)'!$B:$B, '資料源(請謹慎編輯)'!Z:Z, 0)}
A10: 手套 | B10: 司令官手套(質變) | C10: {=XLOOKUP($B10, '資料源(請謹慎編輯)'!$B:$B, '資料源(請謹慎編輯)'!C:C, 0)} | D10: {=XLOOKUP($B10, '資料源(請謹慎編輯)'!$B:$B, '資料源(請謹慎編輯)'!D:D, 0)} | E10: {=XLOOKUP($B10, '資料源(請謹慎編輯)'!$B:$B, '資料源(請謹慎編輯)'!E:E, 0)} | F10: {=XLOOKUP($B10, '資料源(請謹慎編輯)'!$B:$B, '資料源(請謹慎編輯)'!F:F, 0)} | G10: {=XLOOKUP($B10, '資料源(請謹慎編輯)'!$B:$B, '資料源(請謹慎編輯)'!G:G, 0)} | H10: {=XLOOKUP($B10, '資料源(請謹慎編輯)'!$B:$B, '資料源(請謹慎編輯)'!H:H, 0)} | I10: {=XLOOKUP($B10, '資料源(請謹慎編輯)'!$B:$B, '資料源(請謹慎編輯)'!I:I, 0)} | J10: {=XLOOKUP($B10, '資料源(請謹慎編輯)'!$B:$B, '資料源(請謹慎編輯)'!J:J, 0)} | K10: {=XLOOKUP($B10, '資料源(請謹慎編輯)'!$B:$B, '資料源(請謹慎編輯)'!K:K, 0)} | L10: {=XLOOKUP($B10, '資料源(請謹慎編輯)'!$B:$B, '資料源(請謹慎編輯)'!L:L, 0)} | M10: {=XLOOKUP($B10, '資料源(請謹慎編輯)'!$B:$B, '資料源(請謹慎編輯)'!M:M, 0)} | N10: {=XLOOKUP($B10, '資料源(請謹慎編輯)'!$B:$B, '資料源(請謹慎編輯)'!N:N, 0)} | O10: {=XLOOKUP($B10, '資料源(請謹慎編輯)'!$B:$B, '資料源(請謹慎編輯)'!O:O, 0)} | P10: {=XLOOKUP($B10, '資料源(請謹慎編輯)'!$B:$B, '資料源(請謹慎編輯)'!P:P, 0)} | Q10: {=XLOOKUP($B10, '資料源(請謹慎編輯)'!$B:$B, '資料源(請謹慎編輯)'!Q:Q, 0)} | R10: {=XLOOKUP($B10, '資料源(請謹慎編輯)'!$B:$B, '資料源(請謹慎編輯)'!R:R, 0)} | S10: {=XLOOKUP($B10, '資料源(請謹慎編輯)'!$B:$B, '資料源(請謹慎編輯)'!S:S, 0)} | T10: {=XLOOKUP($B10, '資料源(請謹慎編輯)'!$B:$B, '資料源(請謹慎編輯)'!T:T, 0)} | U10: {=XLOOKUP($B10, '資料源(請謹慎編輯)'!$B:$B, '資料源(請謹慎編輯)'!U:U, 0)} | V10: {=XLOOKUP($B10, '資料源(請謹慎編輯)'!$B:$B, '資料源(請謹慎編輯)'!V:V, 0)} | W10: {=XLOOKUP($B10, '資料源(請謹慎編輯)'!$B:$B, '資料源(請謹慎編輯)'!W:W, 0)} | X10: {=XLOOKUP($B10, '資料源(請謹慎編輯)'!$B:$B, '資料源(請謹慎編輯)'!X:X, 0)} | Y10: {=XLOOKUP($B10, '資料源(請謹慎編輯)'!$B:$B, '資料源(請謹慎編輯)'!Y:Y, 0)} | Z10: {=XLOOKUP($B10, '資料源(請謹慎編輯)'!$B:$B, '資料源(請謹慎編輯)'!Z:Z, 0)}
A11: 鞋子 | B11: 提督長筒靴(質變) | C11: {=XLOOKUP($B11, '資料源(請謹慎編輯)'!$B:$B, '資料源(請謹慎編輯)'!C:C, 0)} | D11: {=XLOOKUP($B11, '資料源(請謹慎編輯)'!$B:$B, '資料源(請謹慎編輯)'!D:D, 0)} | E11: {=XLOOKUP($B11, '資料源(請謹慎編輯)'!$B:$B, '資料源(請謹慎編輯)'!E:E, 0)} | F11: {=XLOOKUP($B11, '資料源(請謹慎編輯)'!$B:$B, '資料源(請謹慎編輯)'!F:F, 0)} | G11: {=XLOOKUP($B11, '資料源(請謹慎編輯)'!$B:$B, '資料源(請謹慎編輯)'!G:G, 0)} | H11: {=XLOOKUP($B11, '資料源(請謹慎編輯)'!$B:$B, '資料源(請謹慎編輯)'!H:H, 0)} | I11: {=XLOOKUP($B11, '資料源(請謹慎編輯)'!$B:$B, '資料源(請謹慎編輯)'!I:I, 0)} | J11: {=XLOOKUP($B11, '資料源(請謹慎編輯)'!$B:$B, '資料源(請謹慎編輯)'!J:J, 0)} | K11: {=XLOOKUP($B11, '資料源(請謹慎編輯)'!$B:$B, '資料源(請謹慎編輯)'!K:K, 0)} | L11: {=XLOOKUP($B11, '資料源(請謹慎編輯)'!$B:$B, '資料源(請謹慎編輯)'!L:L, 0)} | M11: {=XLOOKUP($B11, '資料源(請謹慎編輯)'!$B:$B, '資料源(請謹慎編輯)'!M:M, 0)} | N11: {=XLOOKUP($B11, '資料源(請謹慎編輯)'!$B:$B, '資料源(請謹慎編輯)'!N:N, 0)} | O11: {=XLOOKUP($B11, '資料源(請謹慎編輯)'!$B:$B, '資料源(請謹慎編輯)'!O:O, 0)} | P11: {=XLOOKUP($B11, '資料源(請謹慎編輯)'!$B:$B, '資料源(請謹慎編輯)'!P:P, 0)} | Q11: {=XLOOKUP($B11, '資料源(請謹慎編輯)'!$B:$B, '資料源(請謹慎編輯)'!Q:Q, 0)} | R11: {=XLOOKUP($B11, '資料源(請謹慎編輯)'!$B:$B, '資料源(請謹慎編輯)'!R:R, 0)} | S11: {=XLOOKUP($B11, '資料源(請謹慎編輯)'!$B:$B, '資料源(請謹慎編輯)'!S:S, 0)} | T11: {=XLOOKUP($B11, '資料源(請謹慎編輯)'!$B:$B, '資料源(請謹慎編輯)'!T:T, 0)} | U11: {=XLOOKUP($B11, '資料源(請謹慎編輯)'!$B:$B, '資料源(請謹慎編輯)'!U:U, 0)} | V11: {=XLOOKUP($B11, '資料源(請謹慎編輯)'!$B:$B, '資料源(請謹慎編輯)'!V:V, 0)} | W11: {=XLOOKUP($B11, '資料源(請謹慎編輯)'!$B:$B, '資料源(請謹慎編輯)'!W:W, 0)} | X11: {=XLOOKUP($B11, '資料源(請謹慎編輯)'!$B:$B, '資料源(請謹慎編輯)'!X:X, 0)} | Y11: {=XLOOKUP($B11, '資料源(請謹慎編輯)'!$B:$B, '資料源(請謹慎編輯)'!Y:Y, 0)} | Z11: {=XLOOKUP($B11, '資料源(請謹慎編輯)'!$B:$B, '資料源(請謹慎編輯)'!Z:Z, 0)}
A12: 職業 | B12: 大提督/海軍陸戰隊 | C12: {=XLOOKUP($B12, '資料源(請謹慎編輯)'!$B$301:$B$311, '資料源(請謹慎編輯)'!C$301:C$311, 0)} | D12: {=XLOOKUP($B12, '資料源(請謹慎編輯)'!$B$301:$B$311, '資料源(請謹慎編輯)'!D$301:D$311, 0)} | E12: {=XLOOKUP($B12, '資料源(請謹慎編輯)'!$B$301:$B$311, '資料源(請謹慎編輯)'!E$301:E$311, 0)} | F12: {=XLOOKUP($B12, '資料源(請謹慎編輯)'!$B$301:$B$311, '資料源(請謹慎編輯)'!F$301:F$311, 0)} | G12: {=XLOOKUP($B12, '資料源(請謹慎編輯)'!$B$301:$B$311, '資料源(請謹慎編輯)'!G$301:G$311, 0)} | H12: {=XLOOKUP($B12, '資料源(請謹慎編輯)'!$B$301:$B$311, '資料源(請謹慎編輯)'!H$301:H$311, 0)} | I12: {=XLOOKUP($B12, '資料源(請謹慎編輯)'!$B$301:$B$311, '資料源(請謹慎編輯)'!I$301:I$311, 0)} | J12: {=XLOOKUP($B12, '資料源(請謹慎編輯)'!$B$301:$B$311, '資料源(請謹慎編輯)'!J$301:J$311, 0)} | ... Z12: {=XLOOKUP($B12, '資料源(請謹慎編輯)'!$B$301:$B$311, '資料源(請謹慎編輯)'!Z$301:Z$311, 0)}
A13: 角色上限 | C13: {=XLOOKUP($B12, '資料源(請謹慎編輯)'!$B$301:$B$311, '資料源(請謹慎編輯)'!C$315:C$324, 0)} | D13: {=XLOOKUP($B12, '資料源(請謹慎編輯)'!$B$301:$B$311, '資料源(請謹慎編輯)'!D$315:D$324, 0)} | E13: {=XLOOKUP($B12, '資料源(請謹慎編輯)'!$B$301:$B$311, '資料源(請謹慎編輯)'!E$315:E$324, 0)} | F13: {=XLOOKUP($B12, '資料源(請謹慎編輯)'!$B$301:$B$311, '資料源(請謹慎編輯)'!F$315:F$324, 0)} | G13: {=XLOOKUP($B12, '資料源(請謹慎編輯)'!$B$301:$B$311, '資料源(請謹慎編輯)'!G$315:G$324, 0)} | H13: {=XLOOKUP($B12, '資料源(請謹慎編輯)'!$B$301:$B$311, '資料源(請謹慎編輯)'!H$315:H$324, 0)} | I13: {=XLOOKUP($B12, '資料源(請謹慎編輯)'!$B$301:$B$311, '資料源(請謹慎編輯)'!I$315:I$324, 0)} | J13: {=XLOOKUP($B12, '資料源(請謹慎編輯)'!$B$301:$B$311, '資料源(請謹慎編輯)'!J$315:J$324, 0)} | ... Z13: {=XLOOKUP($B12, '資料源(請謹慎編輯)'!$B$301:$B$311, '資料源(請謹慎編輯)'!Z$315:Z$324, 0)}
A14: 航海士 | C14: 1 | D14: 1 | E14: 1 | F14: 1 | G14: 1 | H14: 1 | I14: 1 | J14: 2 | K14: 1 | L14: 1 | M14: 1 | N14: 2 | O14: 1 | P14: 1 | Q14: 1 | R14: 1 | S14: 1 | T14: 1 | W14: 1 | X14: 1 | Y14: 1 | Z14: 1
A15: 加總 | C15: =SUM(C2:C14) | D15: =SUM(D2:D14) | E15: =SUM(E2:E14) | F15: =SUM(F2:F14) | G15: =SUM(G2:G14) | H15: =SUM(H2:H14) | I15: =SUM(I2:I14) | J15: =SUM(J2:J14) | ... Z15: =SUM(Z2:Z14)
K21: 製作者：鎮魂歌

Sheet 炮船範例
A1: 位置 | B1: 裝備名稱 | C1: 炮術 | D1: 水平射擊 | E1: 速射 | F1: 貫穿 | G1: 彈道學 | H1: 水雷 | I1: 齊射 | J1: 修理 | K1: 掠奪 | L1: 迴避 | M1: 應急 | N1: 手術 | O1: 划船 | P1: 劍術 | Q1: 突擊 | R1: 戰術 | S1: 射擊 | T1: 防禦 | U1: 識破 | V1: 猛擊 | W1: 迅捷 | X1: 接舷 | Y1: 操舵 | Z1: 搜尋
A2: 飾品 | B2: 丁卡族戒指 | C2: {=XLOOKUP($B2, '資料源(請謹慎編輯)'!$B:$B, '資料源(請謹慎編輯)'!C:C, 0)} | D2: {=XLOOKUP($B2, '資料源(請謹慎編輯)'!$B:$B, '資料源(請謹慎編輯)'!D:D, 0)} | E2: {=XLOOKUP($B2, '資料源(請謹慎編輯)'!$B:$B, '資料源(請謹慎編輯)'!E:E, 0)} | F2: {=XLOOKUP($B2, '資料源(請謹慎編輯)'!$B:$B, '資料源(請謹慎編輯)'!F:F, 0)} | G2: {=XLOOKUP($B2, '資料源(請謹慎編輯)'!$B:$B, '資料源(請謹慎編輯)'!G:G, 0)} | H2: {=XLOOKUP($B2, '資料源(請謹慎編輯)'!$B:$B, '資料源(請謹慎編輯)'!H:H, 0)} | I2: {=XLOOKUP($B2, '資料源(請謹慎編輯)'!$B:$B, '資料源(請謹慎編輯)'!I:I, 0)} | J2: {=XLOOKUP($B2, '資料源(請謹慎編輯)'!$B:$B, '資料源(請謹慎編輯)'!J:J, 0)} | K2: {=XLOOKUP($B2, '資料源(請謹慎編輯)'!$B:$B, '資料源(請謹慎編輯)'!K:K, 0)} | L2: {=XLOOKUP($B2, '資料源(請謹慎編輯)'!$B:$B, '資料源(請謹慎編輯)'!L:L, 0)} | M2: {=XLOOKUP($B2, '資料源(請謹慎編輯)'!$B:$B, '資料源(請謹慎編輯)'!M:M, 0)} | N2: {=XLOOKUP($B2, '資料源(請謹慎編輯)'!$B:$B, '資料源(請謹慎編輯)'!N:N, 0)} | O2: {=XLOOKUP($B2, '資料源(請謹慎編輯)'!$B:$B, '資料源(請謹慎編輯)'!O:O, 0)} | P2: {=XLOOKUP($B2, '資料源(請謹慎編輯)'!$B:$B, '資料源(請謹慎編輯)'!P:P, 0)} | Q2: {=XLOOKUP($B2, '資料源(請謹慎編輯)'!$B:$B, '資料源(請謹慎編輯)'!Q:Q, 0)} | R2: {=XLOOKUP($B2, '資料源(請謹慎編輯)'!$B:$B, '資料源(請謹慎編輯)'!R:R, 0)} | S2: {=XLOOKUP($B2, '資料源(請謹慎編輯)'!$B:$B, '資料源(請謹慎編輯)'!S:S, 0)} | T2: {=XLOOKUP($B2, '資料源(請謹慎編輯)'!$B:$B, '資料源(請謹慎編輯)'!T:T, 0)} | U2: {=XLOOKUP($B2, '資料源(請謹慎編輯)'!$B:$B, '資料源(請謹慎編輯)'!U:U, 0)} | V2: {=XLOOKUP($B2, '資料源(請謹慎編輯)'!$B:$B, '資料源(請謹慎編輯)'!V:V, 0)} | W2: {=XLOOKUP($B2, '資料源(請謹慎編輯)'!$B:$B, '資料源(請謹慎編輯)'!W:W, 0)} | X2: {=XLOOKUP($B2, '資料源(請謹慎編輯)'!$B:$B, '資料源(請謹慎編輯)'!X:X, 0)} | Y2: {=XLOOKUP($B2, '資料源(請謹慎編輯)'!$B:$B, '資料源(請謹慎編輯)'!Y:Y, 0)} | Z2: {=XLOOKUP($B2, '資料源(請謹慎編輯)'!$B:$B, '資料源(請謹慎編輯)'!Z:Z, 0)}
A3: 飾品 | B3: 丁卡族戒指 | C3: {=XLOOKUP($B3, '資料源(請謹慎編輯)'!$B:$B, '資料源(請謹慎編輯)'!C:C, 0)} | D3: {=XLOOKUP($B3, '資料源(請謹慎編輯)'!$B:$B, '資料源(請謹慎編輯)'!D:D, 0)} | E3: {=XLOOKUP($B3, '資料源(請謹慎編輯)'!$B:$B, '資料源(請謹慎編輯)'!E:E, 0)} | F3: {=XLOOKUP($B3, '資料源(請謹慎編輯)'!$B:$B, '資料源(請謹慎編輯)'!F:F, 0)} | G3: {=XLOOKUP($B3, '資料源(請謹慎編輯)'!$B:$B, '資料源(請謹慎編輯)'!G:G, 0)} | H3: {=XLOOKUP($B3, '資料源(請謹慎編輯)'!$B:$B, '資料源(請謹慎編輯)'!H:H, 0)} | I3: {=XLOOKUP($B3, '資料源(請謹慎編輯)'!$B:$B, '資料源(請謹慎編輯)'!I:I, 0)} | J3: {=XLOOKUP($B3, '資料源(請謹慎編輯)'!$B:$B, '資料源(請謹慎編輯)'!J:J, 0)} | K3: {=XLOOKUP($B3, '資料源(請謹慎編輯)'!$B:$B, '資料源(請謹慎編輯)'!K:K, 0)} | L3: {=XLOOKUP($B3, '資料源(請謹慎編輯)'!$B:$B, '資料源(請謹慎編輯)'!L:L, 0)} | M3: {=XLOOKUP($B3, '資料源(請謹慎編輯)'!$B:$B, '資料源(請謹慎編輯)'!M:M, 0)} | N3: {=XLOOKUP($B3, '資料源(請謹慎編輯)'!$B:$B, '資料源(請謹慎編輯)'!N:N, 0)} | O3: {=XLOOKUP($B3, '資料源(請謹慎編輯)'!$B:$B, '資料源(請謹慎編輯)'!O:O, 0)} | P3: {=XLOOKUP($B3, '資料源(請謹慎編輯)'!$B:$B, '資料源(請謹慎編輯)'!P:P, 0)} | Q3: {=XLOOKUP($B3, '資料源(請謹慎編輯)'!$B:$B, '資料源(請謹慎編輯)'!Q:Q, 0)} | R3: {=XLOOKUP($B3, '資料源(請謹慎編輯)'!$B:$B, '資料源(請謹慎編輯)'!R:R, 0)} | S3: {=XLOOKUP($B3, '資料源(請謹慎編輯)'!$B:$B, '資料源(請謹慎編輯)'!S:S, 0)} | T3: {=XLOOKUP($B3, '資料源(請謹慎編輯)'!$B:$B, '資料源(請謹慎編輯)'!T:T, 0)} | U3: {=XLOOKUP($B3, '資料源(請謹慎編輯)'!$B:$B, '資料源(請謹慎編輯)'!U:U, 0)} | V3: {=XLOOKUP($B3, '資料源(請謹慎編輯)'!$B:$B, '資料源(請謹慎編輯)'!V:V, 0)} | W3: {=XLOOKUP($B3, '資料源(請謹慎編輯)'!$B:$B, '資料源(請謹慎編輯)'!W:W, 0)} | X3: {=XLOOKUP($B3, '資料源(請謹慎編輯)'!$B:$B, '資料源(請謹慎編輯)'!X:X, 0)} | Y3: {=XLOOKUP($B3, '資料源(請謹慎編輯)'!$B:$B, '資料源(請謹慎編輯)'!Y:Y, 0)} | Z3: {=XLOOKUP($B3, '資料源(請謹慎編輯)'!$B:$B, '資料源(請謹慎編輯)'!Z:Z, 0)}
A4: 寶物 | B4: 軍神的護身符 | C4: {=XLOOKUP($B4, '資料源(請謹慎編輯)'!$B:$B, '資料源(請謹慎編輯)'!C:C, 0)} | D4: {=XLOOKUP($B4, '資料源(請謹慎編輯)'!$B:$B, '資料源(請謹慎編輯)'!D:D, 0)} | E4: {=XLOOKUP($B4, '資料源(請謹慎編輯)'!$B:$B, '資料源(請謹慎編輯)'!E:E, 0)} | F4: {=XLOOKUP($B4, '資料源(請謹慎編輯)'!$B:$B, '資料源(請謹慎編輯)'!F:F, 0)} | G4: {=XLOOKUP($B4, '資料源(請謹慎編輯)'!$B:$B, '資料源(請謹慎編輯)'!G:G, 0)} | H4: {=XLOOKUP($B4, '資料源(請謹慎編輯)'!$B:$B, '資料源(請謹慎編輯)'!H:H, 0)} | I4: {=XLOOKUP($B4, '資料源(請謹慎編輯)'!$B:$B, '資料源(請謹慎編輯)'!I:I, 0)} | J4: {=XLOOKUP($B4, '資料源(請謹慎編輯)'!$B:$B, '資料源(請謹慎編輯)'!J:J, 0)} | K4: {=XLOOKUP($B4, '資料源(請謹慎編輯)'!$B:$B, '資料源(請謹慎編輯)'!K:K, 0)} | L4: {=XLOOKUP($B4, '資料源(請謹慎編輯)'!$B:$B, '資料源(請謹慎編輯)'!L:L, 0)} | M4: {=XLOOKUP($B4, '資料源(請謹慎編輯)'!$B:$B, '資料源(請謹慎編輯)'!M:M, 0)} | N4: {=XLOOKUP($B4, '資料源(請謹慎編輯)'!$B:$B, '資料源(請謹慎編輯)'!N:N, 0)} | O4: {=XLOOKUP($B4, '資料源(請謹慎編輯)'!$B:$B, '資料源(請謹慎編輯)'!O:O, 0)} | P4: {=XLOOKUP($B4, '資料源(請謹慎編輯)'!$B:$B, '資料源(請謹慎編輯)'!P:P, 0)} | Q4: {=XLOOKUP($B4, '資料源(請謹慎編輯)'!$B:$B, '資料源(請謹慎編輯)'!Q:Q, 0)} | R4: {=XLOOKUP($B4, '資料源(請謹慎編輯)'!$B:$B, '資料源(請謹慎編輯)'!R:R, 0)} | S4: {=XLOOKUP($B4, '資料源(請謹慎編輯)'!$B:$B, '資料源(請謹慎編輯)'!S:S, 0)} | T4: {=XLOOKUP($B4, '資料源(請謹慎編輯)'!$B:$B, '資料源(請謹慎編輯)'!T:T, 0)} | U4: {=XLOOKUP($B4, '資料源(請謹慎編輯)'!$B:$B, '資料源(請謹慎編輯)'!U:U, 0)} | V4: {=XLOOKUP($B4, '資料源(請謹慎編輯)'!$B:$B, '資料源(請謹慎編輯)'!V:V, 0)} | W4: {=XLOOKUP($B4, '資料源(請謹慎編輯)'!$B:$B, '資料源(請謹慎編輯)'!W:W, 0)} | X4: {=XLOOKUP($B4, '資料源(請謹慎編輯)'!$B:$B, '資料源(請謹慎編輯)'!X:X, 0)} | Y4: {=XLOOKUP($B4, '資料源(請謹慎編輯)'!$B:$B, '資料源(請謹慎編輯)'!Y:Y, 0)} | Z4: {=XLOOKUP($B4, '資料源(請謹慎編輯)'!$B:$B, '資料源(請謹慎編輯)'!Z:Z, 0)}
A5: 寶物 | B5: 軍神的護身符 | C5: {=XLOOKUP($B5, '資料源(請謹慎編輯)'!$B:$B, '資料源(請謹慎編輯)'!C:C, 0)} | D5: {=XLOOKUP($B5, '資料源(請謹慎編輯)'!$B:$B, '資料源(請謹慎編輯)'!D:D, 0)} | E5: {=XLOOKUP($B5, '資料源(請謹慎編輯)'!$B:$B, '資料源(請謹慎編輯)'!E:E, 0)} | F5: {=XLOOKUP($B5, '資料源(請謹慎編輯)'!$B:$B, '資料源(請謹慎編輯)'!F:F, 0)} | G5: {=XLOOKUP($B5, '資料源(請謹慎編輯)'!$B:$B, '資料源(請謹慎編輯)'!G:G, 0)} | H5: {=XLOOKUP($B5, '資料源(請謹慎編輯)'!$B:$B, '資料源(請謹慎編輯)'!H:H, 0)} | I5: {=XLOOKUP($B5, '資料源(請謹慎編輯)'!$B:$B, '資料源(請謹慎編輯)'!I:I, 0)} | J5: {=XLOOKUP($B5, '資料源(請謹慎編輯)'!$B:$B, '資料源(請謹慎編輯)'!J:J, 0)} | K5: {=XLOOKUP($B5, '資料源(請謹慎編輯)'!$B:$B, '資料源(請謹慎編輯)'!K:K, 0)} | L5: {=XLOOKUP($B5, '資料源(請謹慎編輯)'!$B:$B, '資料源(請謹慎編輯)'!L:L, 0)} | M5: {=XLOOKUP($B5, '資料源(請謹慎編輯)'!$B:$B, '資料源(請謹慎編輯)'!M:M, 0)} | N5: {=XLOOKUP($B5, '資料源(請謹慎編輯)'!$B:$B, '資料源(請謹慎編輯)'!N:N, 0)} | O5: {=XLOOKUP($B5, '資料源(請謹慎編輯)'!$B:$B, '資料源(請謹慎編輯)'!O:O, 0)} | P5: {=XLOOKUP($B5, '資料源(請謹慎編輯)'!$B:$B, '資料源(請謹慎編輯)'!P:P, 0)} | Q5: {=XLOOKUP($B5, '資料源(請謹慎編輯)'!$B:$B, '資料源(請謹慎編輯)'!Q:Q, 0)} | R5: {=XLOOKUP($B5, '資料源(請謹慎編輯)'!$B:$B, '資料源(請謹慎編輯)'!R:R, 0)} | S5: {=XLOOKUP($B5, '資料源(請謹慎編輯)'!$B:$B, '資料源(請謹慎編輯)'!S:S, 0)} | T5: {=XLOOKUP($B5, '資料源(請謹慎編輯)'!$B:$B, '資料源(請謹慎編輯)'!T:T, 0)} | U5: {=XLOOKUP($B5, '資料源(請謹慎編輯)'!$B:$B, '資料源(請謹慎編輯)'!U:U, 0)} | V5: {=XLOOKUP($B5, '資料源(請謹慎編輯)'!$B:$B, '資料源(請謹慎編輯)'!V:V, 0)} | W5: {=XLOOKUP($B5, '資料源(請謹慎編輯)'!$B:$B, '資料源(請謹慎編輯)'!W:W, 0)} | X5: {=XLOOKUP($B5, '資料源(請謹慎編輯)'!$B:$B, '資料源(請謹慎編輯)'!X:X, 0)} | Y5: {=XLOOKUP($B5, '資料源(請謹慎編輯)'!$B:$B, '資料源(請謹慎編輯)'!Y:Y, 0)} | Z5: {=XLOOKUP($B5, '資料源(請謹慎編輯)'!$B:$B, '資料源(請謹慎編輯)'!Z:Z, 0)}
A6: 主武 | B6: 馬木魯克的弓 | C6: {=XLOOKUP($B6, '資料源(請謹慎編輯)'!$B:$B, '資料源(請謹慎編輯)'!C:C, 0)} | D6: {=XLOOKUP($B6, '資料源(請謹慎編輯)'!$B:$B, '資料源(請謹慎編輯)'!D:D, 0)} | E6: {=XLOOKUP($B6, '資料源(請謹慎編輯)'!$B:$B, '資料源(請謹慎編輯)'!E:E, 0)} | F6: {=XLOOKUP($B6, '資料源(請謹慎編輯)'!$B:$B, '資料源(請謹慎編輯)'!F:F, 0)} | G6: {=XLOOKUP($B6, '資料源(請謹慎編輯)'!$B:$B, '資料源(請謹慎編輯)'!G:G, 0)} | H6: {=XLOOKUP($B6, '資料源(請謹慎編輯)'!$B:$B, '資料源(請謹慎編輯)'!H:H, 0)} | I6: {=XLOOKUP($B6, '資料源(請謹慎編輯)'!$B:$B, '資料源(請謹慎編輯)'!I:I, 0)} | J6: {=XLOOKUP($B6, '資料源(請謹慎編輯)'!$B:$B, '資料源(請謹慎編輯)'!J:J, 0)} | K6: {=XLOOKUP($B6, '資料源(請謹慎編輯)'!$B:$B, '資料源(請謹慎編輯)'!K:K, 0)} | L6: {=XLOOKUP($B6, '資料源(請謹慎編輯)'!$B:$B, '資料源(請謹慎編輯)'!L:L, 0)} | M6: {=XLOOKUP($B6, '資料源(請謹慎編輯)'!$B:$B, '資料源(請謹慎編輯)'!M:M, 0)} | N6: {=XLOOKUP($B6, '資料源(請謹慎編輯)'!$B:$B, '資料源(請謹慎編輯)'!N:N, 0)} | O6: {=XLOOKUP($B6, '資料源(請謹慎編輯)'!$B:$B, '資料源(請謹慎編輯)'!O:O, 0)} | P6: {=XLOOKUP($B6, '資料源(請謹慎編輯)'!$B:$B, '資料源(請謹慎編輯)'!P:P, 0)} | Q6: {=XLOOKUP($B6, '資料源(請謹慎編輯)'!$B:$B, '資料源(請謹慎編輯)'!Q:Q, 0)} | R6: {=XLOOKUP($B6, '資料源(請謹慎編輯)'!$B:$B, '資料源(請謹慎編輯)'!R:R, 0)} | S6: {=XLOOKUP($B6, '資料源(請謹慎編輯)'!$B:$B, '資料源(請謹慎編輯)'!S:S, 0)} | T6: {=XLOOKUP($B6, '資料源(請謹慎編輯)'!$B:$B, '資料源(請謹慎編輯)'!T:T, 0)} | U6: {=XLOOKUP($B6, '資料源(請謹慎編輯)'!$B:$B, '資料源(請謹慎編輯)'!U:U, 0)} | V6: {=XLOOKUP($B6, '資料源(請謹慎編輯)'!$B:$B, '資料源(請謹慎編輯)'!V:V, 0)} | W6: {=XLOOKUP($B6, '資料源(請謹慎編輯)'!$B:$B, '資料源(請謹慎編輯)'!W:W, 0)} | X6: {=XLOOKUP($B6, '資料源(請謹慎編輯)'!$B:$B, '資料源(請謹慎編輯)'!X:X, 0)} | Y6: {=XLOOKUP($B6, '資料源(請謹慎編輯)'!$B:$B, '資料源(請謹慎編輯)'!Y:Y, 0)} | Z6: {=XLOOKUP($B6, '資料源(請謹慎編輯)'!$B:$B, '資料源(請謹慎編輯)'!Z:Z, 0)}
A7: 副武 | B7: 波斯單刃短劍 | C7: {=XLOOKUP($B7, '資料源(請謹慎編輯)'!$B:$B, '資料源(請謹慎編輯)'!C:C, 0)} | D7: {=XLOOKUP($B7, '資料源(請謹慎編輯)'!$B:$B, '資料源(請謹慎編輯)'!D:D, 0)} | E7: {=XLOOKUP($B7, '資料源(請謹慎編輯)'!$B:$B, '資料源(請謹慎編輯)'!E:E, 0)} | F7: {=XLOOKUP($B7, '資料源(請謹慎編輯)'!$B:$B, '資料源(請謹慎編輯)'!F:F, 0)} | G7: {=XLOOKUP($B7, '資料源(請謹慎編輯)'!$B:$B, '資料源(請謹慎編輯)'!G:G, 0)} | H7: {=XLOOKUP($B7, '資料源(請謹慎編輯)'!$B:$B, '資料源(請謹慎編輯)'!H:H, 0)} | I7: {=XLOOKUP($B7, '資料源(請謹慎編輯)'!$B:$B, '資料源(請謹慎編輯)'!I:I, 0)} | J7: {=XLOOKUP($B7, '資料源(請謹慎編輯)'!$B:$B, '資料源(請謹慎編輯)'!J:J, 0)} | K7: {=XLOOKUP($B7, '資料源(請謹慎編輯)'!$B:$B, '資料源(請謹慎編輯)'!K:K, 0)} | L7: {=XLOOKUP($B7, '資料源(請謹慎編輯)'!$B:$B, '資料源(請謹慎編輯)'!L:L, 0)} | M7: {=XLOOKUP($B7, '資料源(請謹慎編輯)'!$B:$B, '資料源(請謹慎編輯)'!M:M, 0)} | N7: {=XLOOKUP($B7, '資料源(請謹慎編輯)'!$B:$B, '資料源(請謹慎編輯)'!N:N, 0)} | O7: {=XLOOKUP($B7, '資料源(請謹慎編輯)'!$B:$B, '資料源(請謹慎編輯)'!O:O, 0)} | P7: {=XLOOKUP($B7, '資料源(請謹慎編輯)'!$B:$B, '資料源(請謹慎編輯)'!P:P, 0)} | Q7: {=XLOOKUP($B7, '資料源(請謹慎編輯)'!$B:$B, '資料源(請謹慎編輯)'!Q:Q, 0)} | R7: {=XLOOKUP($B7, '資料源(請謹慎編輯)'!$B:$B, '資料源(請謹慎編輯)'!R:R, 0)} | S7: {=XLOOKUP($B7, '資料源(請謹慎編輯)'!$B:$B, '資料源(請謹慎編輯)'!S:S, 0)} | T7: {=XLOOKUP($B7, '資料源(請謹慎編輯)'!$B:$B, '資料源(請謹慎編輯)'!T:T, 0)} | U7: {=XLOOKUP($B7, '資料源(請謹慎編輯)'!$B:$B, '資料源(請謹慎編輯)'!U:U, 0)} | V7: {=XLOOKUP($B7, '資料源(請謹慎編輯)'!$B:$B, '資料源(請謹慎編輯)'!V:V, 0)} | W7: {=XLOOKUP($B7, '資料源(請謹慎編輯)'!$B:$B, '資料源(請謹慎編輯)'!W:W, 0)} | X7: {=XLOOKUP($B7, '資料源(請謹慎編輯)'!$B:$B, '資料源(請謹慎編輯)'!X:X, 0)} | Y7: {=XLOOKUP($B7, '資料源(請謹慎編輯)'!$B:$B, '資料源(請謹慎編輯)'!Y:Y, 0)} | Z7: {=XLOOKUP($B7, '資料源(請謹慎編輯)'!$B:$B, '資料源(請謹慎編輯)'!Z:Z, 0)}
A8: 頭盔 | B8: 阿爾維達的頭盔 | C8: {=XLOOKUP($B8, '資料源(請謹慎編輯)'!$B:$B, '資料源(請謹慎編輯)'!C:C, 0)} | D8: {=XLOOKUP($B8, '資料源(請謹慎編輯)'!$B:$B, '資料源(請謹慎編輯)'!D:D, 0)} | E8: {=XLOOKUP($B8, '資料源(請謹慎編輯)'!$B:$B, '資料源(請謹慎編輯)'!E:E, 0)} | F8: {=XLOOKUP($B8, '資料源(請謹慎編輯)'!$B:$B, '資料源(請謹慎編輯)'!F:F, 0)} | G8: {=XLOOKUP($B8, '資料源(請謹慎編輯)'!$B:$B, '資料源(請謹慎編輯)'!G:G, 0)} | H8: {=XLOOKUP($B8, '資料源(請謹慎編輯)'!$B:$B, '資料源(請謹慎編輯)'!H:H, 0)} | I8: {=XLOOKUP($B8, '資料源(請謹慎編輯)'!$B:$B, '資料源(請謹慎編輯)'!I:I, 0)} | J8: {=XLOOKUP($B8, '資料源(請謹慎編輯)'!$B:$B, '資料源(請謹慎編輯)'!J:J, 0)} | K8: {=XLOOKUP($B8, '資料源(請謹慎編輯)'!$B:$B, '資料源(請謹慎編輯)'!K:K, 0)} | L8: {=XLOOKUP($B8, '資料源(請謹慎編輯)'!$B:$B, '資料源(請謹慎編輯)'!L:L, 0)} | M8: {=XLOOKUP($B8, '資料源(請謹慎編輯)'!$B:$B, '資料源(請謹慎編輯)'!M:M, 0)} | N8: {=XLOOKUP($B8, '資料源(請謹慎編輯)'!$B:$B, '資料源(請謹慎編輯)'!N:N, 0)} | O8: {=XLOOKUP($B8, '資料源(請謹慎編輯)'!$B:$B, '資料源(請謹慎編輯)'!O:O, 0)} | P8: {=XLOOKUP($B8, '資料源(請謹慎編輯)'!$B:$B, '資料源(請謹慎編輯)'!P:P, 0)} | Q8: {=XLOOKUP($B8, '資料源(請謹慎編輯)'!$B:$B, '資料源(請謹慎編輯)'!Q:Q, 0)} | R8: {=XLOOKUP($B8, '資料源(請謹慎編輯)'!$B:$B, '資料源(請謹慎編輯)'!R:R, 0)} | S8: {=XLOOKUP($B8, '資料源(請謹慎編輯)'!$B:$B, '資料源(請謹慎編輯)'!S:S, 0)} | T8: {=XLOOKUP($B8, '資料源(請謹慎編輯)'!$B:$B, '資料源(請謹慎編輯)'!T:T, 0)} | U8: {=XLOOKUP($B8, '資料源(請謹慎編輯)'!$B:$B, '資料源(請謹慎編輯)'!U:U, 0)} | V8: {=XLOOKUP($B8, '資料源(請謹慎編輯)'!$B:$B, '資料源(請謹慎編輯)'!V:V, 0)} | W8: {=XLOOKUP($B8, '資料源(請謹慎編輯)'!$B:$B, '資料源(請謹慎編輯)'!W:W, 0)} | X8: {=XLOOKUP($B8, '資料源(請謹慎編輯)'!$B:$B, '資料源(請謹慎編輯)'!X:X, 0)} | Y8: {=XLOOKUP($B8, '資料源(請謹慎編輯)'!$B:$B, '資料源(請謹慎編輯)'!Y:Y, 0)} | Z8: {=XLOOKUP($B8, '資料源(請謹慎編輯)'!$B:$B, '資料源(請謹慎編輯)'!Z:Z, 0)}
A9: 衣服 | B9: 海軍上將胸甲 | C9: {=XLOOKUP($B9, '資料源(請謹慎編輯)'!$B:$B, '資料源(請謹慎編輯)'!C:C, 0)} | D9: {=XLOOKUP($B9, '資料源(請謹慎編輯)'!$B:$B, '資料源(請謹慎編輯)'!D:D, 0)} | E9: {=XLOOKUP($B9, '資料源(請謹慎編輯)'!$B:$B, '資料源(請謹慎編輯)'!E:E, 0)} | F9: {=XLOOKUP($B9, '資料源(請謹慎編輯)'!$B:$B, '資料源(請謹慎編輯)'!F:F, 0)} | G9: {=XLOOKUP($B9, '資料源(請謹慎編輯)'!$B:$B, '資料源(請謹慎編輯)'!G:G, 0)} | H9: {=XLOOKUP($B9, '資料源(請謹慎編輯)'!$B:$B, '資料源(請謹慎編輯)'!H:H, 0)} | I9: {=XLOOKUP($B9, '資料源(請謹慎編輯)'!$B:$B, '資料源(請謹慎編輯)'!I:I, 0)} | J9: {=XLOOKUP($B9, '資料源(請謹慎編輯)'!$B:$B, '資料源(請謹慎編輯)'!J:J, 0)} | K9: {=XLOOKUP($B9, '資料源(請謹慎編輯)'!$B:$B, '資料源(請謹慎編輯)'!K:K, 0)} | L9: {=XLOOKUP($B9, '資料源(請謹慎編輯)'!$B:$B, '資料源(請謹慎編輯)'!L:L, 0)} | M9: {=XLOOKUP($B9, '資料源(請謹慎編輯)'!$B:$B, '資料源(請謹慎編輯)'!M:M, 0)} | N9: {=XLOOKUP($B9, '資料源(請謹慎編輯)'!$B:$B, '資料源(請謹慎編輯)'!N:N, 0)} | O9: {=XLOOKUP($B9, '資料源(請謹慎編輯)'!$B:$B, '資料源(請謹慎編輯)'!O:O, 0)} | P9: {=XLOOKUP($B9, '資料源(請謹慎編輯)'!$B:$B, '資料源(請謹慎編輯)'!P:P, 0)} | Q9: {=XLOOKUP($B9, '資料源(請謹慎編輯)'!$B:$B, '資料源(請謹慎編輯)'!Q:Q, 0)} | R9: {=XLOOKUP($B9, '資料源(請謹慎編輯)'!$B:$B, '資料源(請謹慎編輯)'!R:R, 0)} | S9: {=XLOOKUP($B9, '資料源(請謹慎編輯)'!$B:$B, '資料源(請謹慎編輯)'!S:S, 0)} | T9: {=XLOOKUP($B9, '資料源(請謹慎編輯)'!$B:$B, '資料源(請謹慎編輯)'!T:T, 0)} | U9: {=XLOOKUP($B9, '資料源(請謹慎編輯)'!$B:$B, '資料源(請謹慎編輯)'!U:U, 0)} | V9: {=XLOOKUP($B9, '資料源(請謹慎編輯)'!$B:$B, '資料源(請謹慎編輯)'!V:V, 0)} | W9: {=XLOOKUP($B9, '資料源(請謹慎編輯)'!$B:$B, '資料源(請謹慎編輯)'!W:W, 0)} | X9: {=XLOOKUP($B9, '資料源(請謹慎編輯)'!$B:$B, '資料源(請謹慎編輯)'!X:X, 0)} | Y9: {=XLOOKUP($B9, '資料源(請謹慎編輯)'!$B:$B, '資料源(請謹慎編輯)'!Y:Y, 0)} | Z9: {=XLOOKUP($B9, '資料源(請謹慎編輯)'!$B:$B, '資料源(請謹慎編輯)'!Z:Z, 0)}
A10: 手套 | B10: 司令官手套 | C10: {=XLOOKUP($B10, '資料源(請謹慎編輯)'!$B:$B, '資料源(請謹慎編輯)'!C:C, 0)} | D10: {=XLOOKUP($B10, '資料源(請謹慎編輯)'!$B:$B, '資料源(請謹慎編輯)'!D:D, 0)} | E10: {=XLOOKUP($B10, '資料源(請謹慎編輯)'!$B:$B, '資料源(請謹慎編輯)'!E:E, 0)} | F10: {=XLOOKUP($B10, '資料源(請謹慎編輯)'!$B:$B, '資料源(請謹慎編輯)'!F:F, 0)} | G10: {=XLOOKUP($B10, '資料源(請謹慎編輯)'!$B:$B, '資料源(請謹慎編輯)'!G:G, 0)} | H10: {=XLOOKUP($B10, '資料源(請謹慎編輯)'!$B:$B, '資料源(請謹慎編輯)'!H:H, 0)} | I10: {=XLOOKUP($B10, '資料源(請謹慎編輯)'!$B:$B, '資料源(請謹慎編輯)'!I:I, 0)} | J10: {=XLOOKUP($B10, '資料源(請謹慎編輯)'!$B:$B, '資料源(請謹慎編輯)'!J:J, 0)} | K10: {=XLOOKUP($B10, '資料源(請謹慎編輯)'!$B:$B, '資料源(請謹慎編輯)'!K:K, 0)} | L10: {=XLOOKUP($B10, '資料源(請謹慎編輯)'!$B:$B, '資料源(請謹慎編輯)'!L:L, 0)} | M10: {=XLOOKUP($B10, '資料源(請謹慎編輯)'!$B:$B, '資料源(請謹慎編輯)'!M:M, 0)} | N10: {=XLOOKUP($B10, '資料源(請謹慎編輯)'!$B:$B, '資料源(請謹慎編輯)'!N:N, 0)} | O10: {=XLOOKUP($B10, '資料源(請謹慎編輯)'!$B:$B, '資料源(請謹慎編輯)'!O:O, 0)} | P10: {=XLOOKUP($B10, '資料源(請謹慎編輯)'!$B:$B, '資料源(請謹慎編輯)'!P:P, 0)} | Q10: {=XLOOKUP($B10, '資料源(請謹慎編輯)'!$B:$B, '資料源(請謹慎編輯)'!Q:Q, 0)} | R10: {=XLOOKUP($B10, '資料源(請謹慎編輯)'!$B:$B, '資料源(請謹慎編輯)'!R:R, 0)} | S10: {=XLOOKUP($B10, '資料源(請謹慎編輯)'!$B:$B, '資料源(請謹慎編輯)'!S:S, 0)} | T10: {=XLOOKUP($B10, '資料源(請謹慎編輯)'!$B:$B, '資料源(請謹慎編輯)'!T:T, 0)} | U10: {=XLOOKUP($B10, '資料源(請謹慎編輯)'!$B:$B, '資料源(請謹慎編輯)'!U:U, 0)} | V10: {=XLOOKUP($B10, '資料源(請謹慎編輯)'!$B:$B, '資料源(請謹慎編輯)'!V:V, 0)} | W10: {=XLOOKUP($B10, '資料源(請謹慎編輯)'!$B:$B, '資料源(請謹慎編輯)'!W:W, 0)} | X10: {=XLOOKUP($B10, '資料源(請謹慎編輯)'!$B:$B, '資料源(請謹慎編輯)'!X:X, 0)} | Y10: {=XLOOKUP($B10, '資料源(請謹慎編輯)'!$B:$B, '資料源(請謹慎編輯)'!Y:Y, 0)} | Z10: {=XLOOKUP($B10, '資料源(請謹慎編輯)'!$B:$B, '資料源(請謹慎編輯)'!Z:Z, 0)}
A11: 鞋子 | B11: 提督長筒靴 | C11: {=XLOOKUP($B11, '資料源(請謹慎編輯)'!$B:$B, '資料源(請謹慎編輯)'!C:C, 0)} | D11: {=XLOOKUP($B11, '資料源(請謹慎編輯)'!$B:$B, '資料源(請謹慎編輯)'!D:D, 0)} | E11: {=XLOOKUP($B11, '資料源(請謹慎編輯)'!$B:$B, '資料源(請謹慎編輯)'!E:E, 0)} | F11: {=XLOOKUP($B11, '資料源(請謹慎編輯)'!$B:$B, '資料源(請謹慎編輯)'!F:F, 0)} | G11: {=XLOOKUP($B11, '資料源(請謹慎編輯)'!$B:$B, '資料源(請謹慎編輯)'!G:G, 0)} | H11: {=XLOOKUP($B11, '資料源(請謹慎編輯)'!$B:$B, '資料源(請謹慎編輯)'!H:H, 0)} | I11: {=XLOOKUP($B11, '資料源(請謹慎編輯)'!$B:$B, '資料源(請謹慎編輯)'!I:I, 0)} | J11: {=XLOOKUP($B11, '資料源(請謹慎編輯)'!$B:$B, '資料源(請謹慎編輯)'!J:J, 0)} | K11: {=XLOOKUP($B11, '資料源(請謹慎編輯)'!$B:$B, '資料源(請謹慎編輯)'!K:K, 0)} | L11: {=XLOOKUP($B11, '資料源(請謹慎編輯)'!$B:$B, '資料源(請謹慎編輯)'!L:L, 0)} | M11: {=XLOOKUP($B11, '資料源(請謹慎編輯)'!$B:$B, '資料源(請謹慎編輯)'!M:M, 0)} | N11: {=XLOOKUP($B11, '資料源(請謹慎編輯)'!$B:$B, '資料源(請謹慎編輯)'!N:N, 0)} | O11: {=XLOOKUP($B11, '資料源(請謹慎編輯)'!$B:$B, '資料源(請謹慎編輯)'!O:O, 0)} | P11: {=XLOOKUP($B11, '資料源(請謹慎編輯)'!$B:$B, '資料源(請謹慎編輯)'!P:P, 0)} | Q11: {=XLOOKUP($B11, '資料源(請謹慎編輯)'!$B:$B, '資料源(請謹慎編輯)'!Q:Q, 0)} | R11: {=XLOOKUP($B11, '資料源(請謹慎編輯)'!$B:$B, '資料源(請謹慎編輯)'!R:R, 0)} | S11: {=XLOOKUP($B11, '資料源(請謹慎編輯)'!$B:$B, '資料源(請謹慎編輯)'!S:S, 0)} | T11: {=XLOOKUP($B11, '資料源(請謹慎編輯)'!$B:$B, '資料源(請謹慎編輯)'!T:T, 0)} | U11: {=XLOOKUP($B11, '資料源(請謹慎編輯)'!$B:$B, '資料源(請謹慎編輯)'!U:U, 0)} | V11: {=XLOOKUP($B11, '資料源(請謹慎編輯)'!$B:$B, '資料源(請謹慎編輯)'!V:V, 0)} | W11: {=XLOOKUP($B11, '資料源(請謹慎編輯)'!$B:$B, '資料源(請謹慎編輯)'!W:W, 0)} | X11: {=XLOOKUP($B11, '資料源(請謹慎編輯)'!$B:$B, '資料源(請謹慎編輯)'!X:X, 0)} | Y11: {=XLOOKUP($B11, '資料源(請謹慎編輯)'!$B:$B, '資料源(請謹慎編輯)'!Y:Y, 0)} | Z11: {=XLOOKUP($B11, '資料源(請謹慎編輯)'!$B:$B, '資料源(請謹慎編輯)'!Z:Z, 0)}
A12: 職業 | B12: 大提督/海軍陸戰隊 | C12: {=XLOOKUP($B12, '資料源(請謹慎編輯)'!$B$301:$B$311, '資料源(請謹慎編輯)'!C$301:C$311, 0)} | D12: {=XLOOKUP($B12, '資料源(請謹慎編輯)'!$B$301:$B$311, '資料源(請謹慎編輯)'!D$301:D$311, 0)} | E12: {=XLOOKUP($B12, '資料源(請謹慎編輯)'!$B$301:$B$311, '資料源(請謹慎編輯)'!E$301:E$311, 0)} | F12: {=XLOOKUP($B12, '資料源(請謹慎編輯)'!$B$301:$B$311, '資料源(請謹慎編輯)'!F$301:F$311, 0)} | G12: {=XLOOKUP($B12, '資料源(請謹慎編輯)'!$B$301:$B$311, '資料源(請謹慎編輯)'!G$301:G$311, 0)} | H12: {=XLOOKUP($B12, '資料源(請謹慎編輯)'!$B$301:$B$311, '資料源(請謹慎編輯)'!H$301:H$311, 0)} | I12: {=XLOOKUP($B12, '資料源(請謹慎編輯)'!$B$301:$B$311, '資料源(請謹慎編輯)'!I$301:I$311, 0)} | J12: {=XLOOKUP($B12, '資料源(請謹慎編輯)'!$B$301:$B$311, '資料源(請謹慎編輯)'!J$301:J$311, 0)} | ... Z12: {=XLOOKUP($B12, '資料源(請謹慎編輯)'!$B$301:$B$311, '資料源(請謹慎編輯)'!Z$301:Z$311, 0)}
A13: 角色上限 | C13: {=XLOOKUP($B12, '資料源(請謹慎編輯)'!$B$301:$B$311, '資料源(請謹慎編輯)'!C$315:C$324, 0)} | D13: {=XLOOKUP($B12, '資料源(請謹慎編輯)'!$B$301:$B$311, '資料源(請謹慎編輯)'!D$315:D$324, 0)} | E13: {=XLOOKUP($B12, '資料源(請謹慎編輯)'!$B$301:$B$311, '資料源(請謹慎編輯)'!E$315:E$324, 0)} | F13: {=XLOOKUP($B12, '資料源(請謹慎編輯)'!$B$301:$B$311, '資料源(請謹慎編輯)'!F$315:F$324, 0)} | G13: {=XLOOKUP($B12, '資料源(請謹慎編輯)'!$B$301:$B$311, '資料源(請謹慎編輯)'!G$315:G$324, 0)} | H13: {=XLOOKUP($B12, '資料源(請謹慎編輯)'!$B$301:$B$311, '資料源(請謹慎編輯)'!H$315:H$324, 0)} | I13: {=XLOOKUP($B12, '資料源(請謹慎編輯)'!$B$301:$B$311, '資料源(請謹慎編輯)'!I$315:I$324, 0)} | J13: {=XLOOKUP($B12, '資料源(請謹慎編輯)'!$B$301:$B$311, '資料源(請謹慎編輯)'!J$315:J$324, 0)} | ... Z13: {=XLOOKUP($B12, '資料源(請謹慎編輯)'!$B$301:$B$311, '資料源(請謹慎編輯)'!Z$315:Z$324, 0)}
A14: 航海士 | C14: 1 | D14: 1 | E14: 1 | F14: 1 | G14: 1 | H14: 1 | I14: 1 | J14: 2 | K14: 1 | L14: 1 | M14: 1 | N14: 2 | O14: 1 | P14: 1 | Q14: 1 | R14: 1 | S14: 1 | T14: 1 | W14: 1 | X14: 1 | Y14: 1 | Z14: 1
A15: 加總 | C15: =SUM(C2:C14) | D15: =SUM(D2:D14) | E15: =SUM(E2:E14) | F15: =SUM(F2:F14) | G15: =SUM(G2:G14) | H15: =SUM(H2:H14) | I15: =SUM(I2:I14) | J15: =SUM(J2:J14) | ... Z15: =SUM(Z2:Z14)
K21: 製作者：鎮魂歌

Sheet 資料源(請謹慎編輯)
A1: 位置 | B1: 裝備名稱 | C1: 炮術 | D1: 水平射擊 | E1: 速射 | F1: 貫穿 | G1: 彈道學 | H1: 水雷 | I1: 齊射 | J1: 修理 | K1: 掠奪 | L1: 迴避 | M1: 應急 | N1: 手術 | O1: 划船 | P1: 劍術 | Q1: 突擊 | R1: 戰術 | S1: 射擊 | T1: 防禦 | U1: 識破 | V1: 猛擊 | W1: 迅捷 | X1: 接舷 | Y1: 操舵 | Z1: 搜尋
A2: 飾品 | B2: 丁卡族戒指 | D2: 1 | E2: 1 | H2: 1
A3: 飾品 | B3: 丁卡族戒指(質變) | D3: 2 | E3: 1 | H3: 1
A4: 飾品 | B4: 漆黑手鐲 | C4: 1 | H4: 1 | I4: 1
A5: 飾品 | B5: 漆黑手鐲(質變) | C5: 1 | H5: 1 | I5: 2
A6: 飾品 | B6: 土庫曼手鐲 | D6: 1 | I6: 1 | K6: 1
A7: 飾品 | B7: 尼布龍根戒指(唯一) | F7: 2 | J7: 1 | K7: 1
A8: 飾品 | B8: 納加族的人面項鍊 | Q8: 1 | T8: 2 | V8: 1
A9: 飾品 | B9: 海盜女王的項鍊 | K9: 1 | N9: 1 | O9: 1
A10: 飾品 | B10: 海盜女王的項鍊(質變) | K10: 1 | L10: 1 | N10: 1 | O10: 1
A11: 飾品 | B11: 芒薩族的項鍊 | T11: 1 | U11: 1 | Z11: 1
A12: 飾品 | B12: 丁卡族手鐲 | L12: 1 | O12: 1 | T12: 1
A13: 飾品 | B13: 丁卡族手鐲(質變) | L13: 2 | O13: 2 | T13: 1
A14: 飾品 | B14: 凱爾特手鐲 | P14: 1 | R14: 1
A15: 飾品 | B15: 印度鱷魚的牙飾 | U15: 1 | V15: 1
A16: 飾品 | B16: 庫丘林的手鐲 | P16: 1 | T16: 1
A17: 飾品 | B17: 指引者項鍊 | G17: 1 | I17: 1 | L17: 1
A18: 飾品 | B18: 曙光的胸針 | C18: 1
A19: 飾品 | B19: 朱利安的戒指 | Z19: 1
A20: 飾品 | B20: 犰狳的鐵皮 | T20: 1
A21: 飾品 | B21: 神造手鐲 | F21: 1 | L21: 1
A22: 飾品 | B22: 紅色花的胸針 | M22: 1
A23: 飾品 | B23: 翡翠項鍊 | S23: 1 | W23: 1
A24: 飾品 | B24: 青銅的手鐲 | M24: 1
A25: 飾品 | B25: 馬賽族的飾環 | Q25: 1 | W25: 1
A26: 位置 | B26: 裝備名稱 | C26: 炮術 | D26: 水平射擊 | E26: 速射 | F26: 貫穿 | G26: 彈道學 | H26: 水雷 | I26: 齊射 | J26: 修理 | K26: 掠奪 | L26: 迴避 | M26: 應急 | N26: 手術 | O26: 划船 | P26: 劍術 | Q26: 突擊 | R26: 戰術 | S26: 射擊 | T26: 防禦 | U26: 識破 | V26: 猛擊 | W26: 迅捷 | X26: 接舷 | Y26: 操舵 | Z26: 搜尋
A27: 寶物 | B27: 軍神的護身符(質變) | C27: 2 | F27: 1 | G27: 1 | H27: 1
A28: 寶物 | B28: 軍神的護身符 | C28: 2 | F28: 1 | G28: 1
A29: 寶物 | B29: 伊西絲的護符 | H29: 1 | K29: 1
A30: 寶物 | B30: 炮術家的手記 | C30: 1 | I30: 1
A31: 寶物 | B31: 黃金心臟 | J31: 2 | M31: 1
A32: 寶物 | B32: 猛將的印章(質變) | M32: 1 | Q32: 2 | R32: 1 | S32: 1
A33: 寶物 | B33: 猛將的印章 | M33: 1 | Q33: 2 | R33: 1
A34: 寶物 | B34: 九柱神之書 | P34: 1 | R34: 1 | S34: 1
A35: 寶物 | B35: 海盜的成規 | K35: 1 | Q35: 1
A36: 寶物 | B36: 溫庫隆庫魯雕像 | U36: 2 | V36: 2
A37: 寶物 | B37: 佐爾齊的毒瓶 | M37: 2 | R37: 2
A38: 寶物 | B38: 佐爾齊的毒瓶(質變) | M38: 2 | R38: 3
A39: 寶物 | B39: 印度女神護符 | J39: 1 | L39: 2 | N39: 2
A40: 寶物 | B40: 印度女神護符(質變) | J40: 1 | L40: 2 | N40: 2
...
